raceback (most recent call last):
  File "/home/bear/projects/tweet-extractor/python/extractor.py", line 54, in <module>
    ext.MainCorpExtraction(api,since,dt.datetime.today(),q)
  File "/home/bear/projects/tweet-extractor/python/extractor.py", line 24, in MainCorpExtraction
    for page in Alltweets:
  File "/home/bear/.local/share/virtualenvs/tweet-extractor-cggEJZCA/lib/python3.9/site-packages/tweepy/cursor.py", line 51, in __next__
    return self.next()
  File "/home/bear/.local/share/virtualenvs/tweet-extractor-cggEJZCA/lib/python3.9/site-packages/tweepy/cursor.py", line 132, in next
    data = self.method(max_id=self.max_id, parser=RawParser(), *self.args, **self.kwargs)
  File "/home/bear/.local/share/virtualenvs/tweet-extractor-cggEJZCA/lib/python3.9/site-packages/tweepy/binder.py", line 253, in _call
    return method.execute()
  File "/home/bear/.local/share/virtualenvs/tweet-extractor-cggEJZCA/lib/python3.9/site-packages/tweepy/binder.py", line 192, in execute
    six.reraise(TweepError, TweepError('Failed to send request: %s' % e), sys.exc_info()[2])
  File "/home/bear/.local/share/virtualenvs/tweet-extractor-cggEJZCA/lib/python3.9/site-packages/six.py", line 702, in reraise
    raise value.with_traceback(tb)
  File "/home/bear/.local/share/virtualenvs/tweet-extractor-cggEJZCA/lib/python3.9/site-packages/tweepy/binder.py", line 184, in execute
    resp = self.session.request(self.method,
  File "/home/bear/.local/share/virtualenvs/tweet-extractor-cggEJZCA/lib/python3.9/site-packages/requests/sessions.py", line 542, in request
    resp = self.send(prep, **send_kwargs)
  File "/home/bear/.local/share/virtualenvs/tweet-extractor-cggEJZCA/lib/python3.9/site-packages/requests/sessions.py", line 655, in send
    r = adapter.send(request, **kwargs)
  File "/home/bear/.local/share/virtualenvs/tweet-extractor-cggEJZCA/lib/python3.9/site-packages/requests/adapters.py", line 516, in send
    raise ConnectionError(e, request=request)
tweepy.error.TweepError: Failed to send request: HTTPSConnectionPool(host='api.twitter.com', port=443): Max retries exceeded with url: /1.1/search/tweets.json?q=TUF+Gaming%0A&since=2021-02-13&until=2021-02-17&count=200 (Caused by NewConnectionError('<urllib3.connection.HTTPSConnection object at 0x7f8bb5884250>: Failed to establish a new connection: [Errno -2] Name or service not known'))
tweepy.error.TweepError: Failed to send request: HTTPSConnectionPool(host='api.twitter.com', port=443): Max retries exceeded with url: /1.1/search/tweets.json?max_id=1360612004067762177&q=Intel%0A&since=2021-02-13&until=2021-02-17&count=200 (Caused by NewConnectionError('<urllib3.connection.HTTPSConnection object at 0x7efbb427a460>: Failed to establish a new connection: [Errno -2] Name or service not known'))